Workbook
Name LIST_BIRD_TYPE: '99_LISTS'!$Y$2:$Y$3
Name LIST_BREED_PIG: '99_LISTS'!$S$2:$S$4
Name LIST_BREED_POULTRY: '99_LISTS'!$Z$2:$Z$5
Name LIST_CHANNEL: '99_LISTS'!$K$2:$K$6
Name LIST_CROP: '99_LISTS'!$AE$2:$AE$7
Name LIST_CURRENCY: '99_LISTS'!$C$2:$C$3
Name LIST_DOMAIN: '99_LISTS'!$A$2:$A$5
Name LIST_EXP_CATEGORY: '99_LISTS'!$F$2:$F$15
Name LIST_FEED_TYPE: '99_LISTS'!$O$2:$O$12
Name LIST_GRADE: '99_LISTS'!$AM$2:$AM$5
Name LIST_GROWTH_STAGE: '99_LISTS'!$AJ$2:$AJ$7
Name LIST_HEALTH_EVENT: '99_LISTS'!$P$2:$P$4
Name LIST_IRRIGATION_TYPE: '99_LISTS'!$AD$2:$AD$5
Name LIST_ISSUE_TYPE: '99_LISTS'!$AK$2:$AK$6
Name LIST_LITTER_CONDITION: '99_LISTS'!$AB$2:$AB$5
Name LIST_OP_TYPE: '99_LISTS'!$AH$2:$AH$11
Name LIST_OUTCOME: '99_LISTS'!$R$2:$R$5
Name LIST_PAY_TYPE: '99_LISTS'!$E$2:$E$4
Name LIST_PAYMENT_METHOD: '99_LISTS'!$H$2:$H$5
Name LIST_PAYMENT_STATUS: '99_LISTS'!$L$2:$L$4
Name LIST_PEN_CONDITION: '99_LISTS'!$V$2:$V$5
Name LIST_PLANTING_STATUS: '99_LISTS'!$AG$2:$AG$4
Name LIST_POULTRY_STATUS: '99_LISTS'!$AA$2:$AA$6
Name LIST_PRODUCT: '99_LISTS'!$I$2:$I$10
Name LIST_ROLE: '99_LISTS'!$D$2:$D$6
Name LIST_SEASON: '99_LISTS'!$AF$2:$AF$5
Name LIST_SERVICE_TYPE: '99_LISTS'!$X$2:$X$3
Name LIST_SOIL_MOISTURE: '99_LISTS'!$AL$2:$AL$4
Name LIST_SOIL_TYPE: '99_LISTS'!$AC$2:$AC$5
Name LIST_SOURCE: '99_LISTS'!$T$2:$T$3
Name LIST_SOW_STATUS: '99_LISTS'!$W$2:$W$6
Name LIST_STATUS_BATCH: '99_LISTS'!$U$2:$U$4
Name LIST_STORAGE: '99_LISTS'!$AN$2:$AN$5
Name LIST_SYMPTOM: '99_LISTS'!$Q$2:$Q$8
Name LIST_TASK: '99_LISTS'!$M$2:$M$11
Name LIST_UNIT_FIELD: '99_LISTS'!$AI$2:$AI$5
Name LIST_UNIT_GENERAL: '99_LISTS'!$G$2:$G$8
Name LIST_UNIT_SALES: '99_LISTS'!$J$2:$J$6
Name LIST_WEATHER_EVENT: '99_LISTS'!$N$2:$N$7
Name LIST_YESNO: '99_LISTS'!$B$2:$B$3

Sheet README
A1: Netrisyl Farm Intelligence — Data Entry Workbook
A3: One workbook per farm. Import this file into Google Sheets (File > Import > Replace spreadsheet) and it becomes the farm's live data-entry sheet.
A5: HOW THE TABS ARE ORGANISED
A6: 00-07 Shared CORE tabs — money, people, weather, feed store, health. Always installed, regardless of which modules a farm runs.
A7: P1-P5 PIGGERY module — remove these tabs entirely for a farm with no pigs.
A8: C1-C3 POULTRY module — remove these tabs entirely for a farm with no birds.
A9: F1-F5 CROPS module — remove these tabs entirely for a farm with no fields.
A10: 99_LISTS Hidden reference tab. Every dropdown pulls its options from here — edit a list once here and every sheet using it updates.
A12: THE THREE JOIN KEYS
A13: farm_code Not repeated on every sheet in this single-farm file, but add it back as the first column on every tab once you consolidate multiple farms into one Supabase project.
A14: domain piggery | poultry | crops | shared — appears on every CORE tab so a query like 'feed cost split between pigs and chickens' is a one-line GROUP BY.
A15: batch_ref / batch_code Links a cost, sale or health event back to a specific pig batch, poultry batch or crop planting for true per-batch profit and loss.
... A35: A daily log should take under 90 seconds per pen/house. A weekly one, under 10 minutes. If a worker can't finish it in the field, it will stop being filled in within a month.

Sheet 99_LISTS
A1: DOMAIN | B1: YESNO | C1: CURRENCY | D1: ROLE | E1: PAY_TYPE | F1: EXP_CATEGORY | G1: UNIT_GENERAL | H1: PAYMENT_METHOD | I1: PRODUCT | J1: UNIT_SALES | K1: CHANNEL | L1: PAYMENT_STATUS | M1: TASK | N1: WEATHER_EVENT | O1: FEED_TYPE | P1: HEALTH_EVENT | Q1: SYMPTOM | R1: OUTCOME | S1: BREED_PIG | T1: SOURCE | U1: STATUS_BATCH | V1: PEN_CONDITION | W1: SOW_STATUS | X1: SERVICE_TYPE | Y1: BIRD_TYPE | Z1: BREED_POULTRY | AA1: POULTRY_STATUS | AB1: LITTER_CONDITION | AC1: SOIL_TYPE | AD1: IRRIGATION_TYPE | AE1: CROP | AF1: SEASON | AG1: PLANTING_STATUS | AH1: OP_TYPE | AI1: UNIT_FIELD | AJ1: GROWTH_STAGE | AK1: ISSUE_TYPE | AL1: SOIL_MOISTURE | AM1: GRADE | AN1: STORAGE
A2: piggery | B2: Yes | C2: USD | D2: Pig attendant | E2: Daily | F2: Feed | G2: kg | H2: Cash | I2: Live pig | J2: kg | K2: Farm gate | L2: Paid | M2: Feeding | N2: Normal | O2: Pig starter | P2: Treatment | Q2: Coughing | R2: Recovered | S2: Large White | T2: Own farrowing | U2: Active | V2: Dry | W2: Open | X2: Natural | Y2: Broiler | Z2: Ross 308 | AA2: Brooding | AB2: Dry | AC2: Sandy | AD2: Rainfed | AE2: Maize | AF2: 2025 Summer | AG2: Growing | AH2: Land prep | AI2: kg | AJ2: Emergence | AK2: Pest | AL2: Dry | AM2: A | AN2: Store room
A3: poultry | B3: No | C3: ZWG | D3: Poultry attendant | E3: Monthly | F3: Day-old chicks | G3: bag | H3: EcoCash | I3: Pork carcass | J3: head | K3: Abattoir | L3: Partial | M3: Cleaning | N3: Heatwave | O3: Pig grower | P3: Vaccination | Q3: Diarrhoea | R3: Died | S3: Landrace | T3: Bought-in | U3: Sold | V3: Damp | W3: Served | X3: AI | Y3: Layer | Z3: Cobb 500 | AA3: Growing | AB3: Damp | AC3: Sandy loam | AD3: Drip | AE3: Soyabean | AF3: 2025 Winter | AG3: Harvested | AH3: Planting | AI3: litre | AJ3: V6 | AK3: Disease | AL3: Moist | AM3: B | AN3: Silo 1
A4: crops | D4: Field hand | E4: Piece-rate | F4: Weaners | G4: litre | H4: Bank | I4: Weaner | J4: tray | K4: Contract | L4: Owing | M4: Weighing | N4: Hailstorm | O4: Pig finisher | P4: Inspection | Q4: Lameness | R4: Culled | S4: Duroc cross | U4: Closed | V4: Wet | W4: Pregnant | Z4: Hy-Line Brown | AA4: Laying | AB4: Caked | AC4: Clay loam | AD4: Sprinkler | AE4: Groundnuts | AF4: 2026 Summer | AG4: Failed | AH4: Basal fert | AI4: ml | AJ4: Tasselling | AK4: Weed | AL4: Wet | AM4: C | AN4: Silo 2
A5: shared | D5: Supervisor | F5: Vet & Meds | G5: head | H5: Credit | I5: Live broiler | J5: bag | K5: Market | M5: Vaccination | N5: Power cut | O5: Sow & weaner meal | Q5: Off-feed | R5: Ongoing | V5: Dirty | W5: Lactating | Z5: Boschveld | AA5: Sold | AB5: Wet | AC5: Red clay | AD5: Flood | AE5: Tomatoes | AF5: 2026 Winter | AH5: Top dressing | AI5: bag | AJ5: Silking | AK5: Nutrient | AM5: Reject | AN5: Sold direct
D6: Casual | F6: Seed | G6: dose | I6: Dressed chicken | J6: crate | K6: Retail | M6: Land prep | N6: Frost | O6: Broiler starter | Q6: Sneezing | W6: Culled | AA6: Closed | AE6: Cabbage | AH6: Herbicide | AJ6: Grain fill | AK6: None
F7: Fertiliser | G7: trip | I7: Table eggs | M7: Weeding | N7: Storm damage | O7: Broiler grower | Q7: Drop in lay | AE7: Sugar beans | AH7: Pesticide | AJ7: Maturity
F8: Chemicals | G8: hour | I8: Maize grain | M8: Spraying | O8: Broiler finisher | Q8: None | AH8: Fungicide
F9: Fuel | I9: Soya | M9: Harvest | O9: Layer mash | AH9: Weeding
F10: Electricity | I10: Tomatoes | M10: Marketing | O10: Chick mash | AH10: Irrigation
F11: Water | M11: Maintenance | O11: Maize bran | AH11: Other
F12: Repairs | O12: Concentrate
F13: Transport
F14: Labour (contract)
F15: Other

Sheet 00_FARM_PROFILE
A1: PURPOSE: Declares which modules are ACTIVE. The chatbot reads this first and refuses to answer for modules that are off. | CADENCE: Once at onboarding, reviewed quarterly | ENTERED BY: Farm owner / Netrisyl onboarding
A2: farm_code | B2: farm_name | C2: region_district | D2: currency | E2: total_hectares | F2: module_piggery_active | G2: module_poultry_active | H2: module_crops_active | I2: financial_year_start
A3: NIS-001 | B3: Chiedza Mixed Farm | C3: Goromonzi, Mashonaland East | D3: USD | E3: 45 | F3: Yes | G3: Yes | H3: Yes | I3: 2026-01-01

Sheet 01_STAFF
A1: PURPOSE: Turns initials scribbled on a paper log into a costable labour record. | CADENCE: On hire / change | ENTERED BY: Owner or supervisor
A2: staff_code | B2: full_name | C2: role | D2: primary_domain | E2: pay_type | F2: rate | G2: active
A3: S01 | B3: Tendai Moyo | C3: Pig attendant | D3: piggery | E3: Daily | F3: 12 | G3: Yes
A4: S02 | B4: Blessing Chikafu | C4: Poultry attendant | D4: poultry | E4: Daily | F4: 11 | G4: Yes
A5: S03 | B5: Farai Gumbo | C5: Field hand | D5: crops | E5: Piece-rate | F5: 8 | G5: Yes
A6: S04 | B6: Rudo Mutasa | C6: Supervisor | D6: shared | E6: Monthly | F6: 450 | G6: Yes

Sheet 02_EXPENSES
A1: PURPOSE: The single money-out ledger for all three domains. The domain column is what makes cross-domain cost questions possible. | CADENCE: Every purchase, same day | ENTERED BY: Owner / bookkeeper (from receipts)
A2: date | B2: domain | C2: category | D2: item | E2: quantity | F2: unit | G2: unit_cost | H2: total_cost | I2: supplier | J2: payment_method | K2: batch_ref | L2: allocation_note | M2: recorded_by
A3: 2026-09-01 | B3: poultry | C3: Feed | D3: Broiler starter 50kg | E3: 10 | F3: bag | G3: 34 | H3: =E3*G3 | I3: Profeeds Marondera | J3: EcoCash | K3: BRO-24 | M3: S01
A4: 2025-10-27 | B4: piggery | C4: Feed | D4: Pig grower 50kg | E4: 5 | F4: bag | G4: 34 | H4: =E4*G4 | I4: Profeeds Marondera | J4: EcoCash | M4: S04
A5: 2025-11-03 | B5: piggery | C5: Feed | D5: Pig grower 50kg | E5: 5 | F5: bag | G5: 34 | H5: =E5*G5 | I5: Profeeds Marondera | J5: Cash | M5: S02
A6: 2025-11-10 | B6: piggery | C6: Feed | D6: Pig grower 50kg | E6: 5 | F6: bag | G6: 34 | H6: =E6*G6 | I6: Profeeds Marondera | J6: EcoCash | M6: S02
A7: 2025-11-17 | B7: piggery | C7: Feed | D7: Pig grower 50kg | E7: 5 | F7: bag | G7: 34 | H7: =E7*G7 | I7: Profeeds Marondera | J7: Cash | M7: S01
A8: 2025-11-24 | B8: piggery | C8: Feed | D8: Pig grower 50kg | E8: 5 | F8: bag | G8: 34 | H8: =E8*G8 | I8: Profeeds Marondera | J8: EcoCash | M8: S01
A9: 2025-12-01 | B9: piggery | C9: Feed | D9: Pig grower 50kg | E9: 5 | F9: bag | G9: 34 | H9: =E9*G9 | I9: Profeeds Marondera | J9: Cash | M9: S02
A10: 2025-12-08 | B10: piggery | C10: Feed | D10: Pig grower 50kg | E10: 5 | F10: bag | G10: 34 | H10: =E10*G10 | I10: Profeeds Marondera | J10: Cash | M10: S02
A11: 2025-12-15 | B11: piggery | C11: Feed | D11: Pig grower 50kg | E11: 7 | F11: bag | G11: 34 | H11: =E11*G11 | I11: Profeeds Marondera | J11: Cash | M11: S01
A12: 2025-12-22 | B12: piggery | C12: Feed | D12: Pig grower 50kg | E12: 7 | F12: bag | G12: 34 | H12: =E12*G12 | I12: Profeeds Marondera | J12: Cash | M12: S04
A13: 2025-12-29 | B13: piggery | C13: Feed | D13: Pig grower 50kg | E13: 7 | F13: bag | G13: 34 | H13: =E13*G13 | I13: Profeeds Marondera | J13: Bank | M13: S02
A14: 2026-01-05 | B14: piggery | C14: Feed | D14: Pig grower 50kg | E14: 9 | F14: bag | G14: 34 | H14: =E14*G14 | I14: Profeeds Marondera | J14: Bank | M14: S02
A15: 2026-01-12 | B15: piggery | C15: Feed | D15: Pig grower 50kg | E15: 10 | F15: bag | G15: 34 | H15: =E15*G15 | I15: Profeeds Marondera | J15: Cash | M15: S04
... A78: 2026-09-14 | B78: poultry | C78: Feed | D78: Broiler grower 50kg | E78: 4 | F78: bag | G78: 37 | H78: =E78*G78 | I78: Profeeds Marondera | J78: Cash | M78: S02
A79: 2026-03-02 | B79: piggery | C79: Weaners | D79: Weaners x26 | E79: 26 | F79: head | G79: 27.97 | H79: =E79*G79 | I79: Local breeder | J79: Cash | K79: PIG-B02 | M79: S01
A80: 2025-11-10 | B80: piggery | C80: Weaners | D80: Weaners x24 | E80: 24 | F80: head | G80: 26.15 | H80: =E80*G80 | I80: Local breeder | J80: Cash | K80: PIG-B03 | M80: S01
A81: 2025-10-10 | B81: poultry | C81: Day-old chicks | D81: Ross 308 day-old chicks | E81: 500 | F81: head | G81: 0.55 | H81: =E81*G81 | I81: Irvine's Zimbabwe | J81: EcoCash | K81: BRO-P01 | M81: S02
A82: 2025-12-20 | B82: poultry | C82: Day-old chicks | D82: Ross 308 day-old chicks | E82: 520 | F82: head | G82: 0.58 | H82: =E82*G82 | I82: Irvine's Zimbabwe | J82: EcoCash | K82: BRO-P02 | M82: S02
A83: 2026-03-05 | B83: poultry | C83: Day-old chicks | D83: Ross 308 day-old chicks | E83: 500 | F83: head | G83: 0.55 | H83: =E83*G83 | I83: Irvine's Zimbabwe | J83: EcoCash | K83: BRO-P03 | M83: S02
A84: 2026-08-04 | B84: poultry | C84: Day-old chicks | D84: Ross 308 day-old chicks | E84: 510 | F84: head | G84: 0.6 | H84: =E84*G84 | I84: National Foods Hatchery | J84: EcoCash | K84: BRO-P04 | M84: S02
A85: 2026-04-25 | B85: piggery | C85: Vet & Meds | D85: Suspected bacterial enteritis / respiratory complex | E85: 1 | F85: dose | G85: 15 | H85: =E85*G85 | I85: Farm & City Vet | J85: Cash | K85: PIG-B02 | M85: S01
A86: 2026-04-27 | B86: piggery | C86: Vet & Meds | D86: Oxytetracycline LA | E86: 1 | F86: dose | G86: 34.98 | H86: =E86*G86 | I86: Farm & City Vet | J86: Cash | K86: PIG-B02 | M86: S01
A87: 2026-04-29 | B87: piggery | C87: Vet & Meds | D87: Oxytetracycline LA | E87: 1 | F87: dose | G87: 40.47 | H87: =E87*G87 | I87: Farm & City Vet | J87: Cash | K87: PIG-B02 | M87: S01
A88: 2026-05-01 | B88: piggery | C88: Vet & Meds | D88: Oxytetracycline LA | E88: 1 | F88: dose | G88: 36.77 | H88: =E88*G88 | I88: Farm & City Vet | J88: Cash | K88: PIG-B02 | M88: S01
A89: 2026-05-05 | B89: piggery | C89: Vet & Meds | D89: Oxytetracycline LA | E89: 1 | F89: dose | G89: 41.33 | H89: =E89*G89 | I89: Farm & City Vet | J89: Cash | K89: PIG-B02 | M89: S01
A90: 2025-11-09 | B90: piggery | C90: Vet & Meds | D90: Erysipelas + Parvo combo | E90: 1 | F90: dose | G90: 9 | H90: =E90*G90 | I90: Farm & City Vet | J90: Cash | K90: PIG-B01 | M90: S01
... A122: 2026-08-06 | B122: crops | C122: Chemicals | D122: Herbicide - Glyphosate | E122: 6 | F122: litre | G122: 7.5 | H122: =E122*G122 | I122: Farm & City | J122: Bank | K122: TM-PL2-26A | M122: S03
A123: 2025-10-01 | B123: shared | C123: Fuel | D123: Diesel - generator/vehicle | E123: 46 | F123: litre | G123: 1.52 | H123: =E123*G123 | I123: Puma Energy Goromonzi | J123: Cash | M123: S04
A124: 2025-10-01 | B124: shared | C124: Electricity | D124: ZESA prepaid token | E124: 1 | F124: trip | G124: 67.33 | H124: =E124*G124 | I124: ZESA | J124: EcoCash | M124: S04
A125: 2025-10-31 | B125: shared | C125: Fuel | D125: Diesel - generator/vehicle | E125: 44 | F125: litre | G125: 1.6 | H125: =E125*G125 | I125: Puma Energy Goromonzi | J125: Cash | M125: S04
A126: 2025-10-31 | B126: shared | C126: Electricity | D126: ZESA prepaid token | E126: 1 | F126: trip | G126: 69.65 | H126: =E126*G126 | I126: ZESA | J126: EcoCash | M126: S04
A127: 2025-11-30 | B127: shared | C127: Fuel | D127: Diesel - generator/vehicle | E127: 37 | F127: litre | G127: 1.55 | H127: =E127*G127 | I127: Puma Energy Goromonzi | J127: Cash | M127: S04
A128: 2025-11-30 | B128: shared | C128: Electricity | D128: ZESA prepaid token | E128: 1 | F128: trip | G128: 61.94 | H128: =E128*G128 | I128: ZESA | J128: EcoCash | M128: S04
A129: 2025-12-30 | B129: shared | C129: Fuel | D129: Diesel - generator/vehicle | E129: 34 | F129: litre | G129: 1.57 | H129: =E129*G129 | I129: Puma Energy Goromonzi | J129: Cash | M129: S04
A130: 2025-12-30 | B130: shared | C130: Electricity | D130: ZESA prepaid token | E130: 1 | F130: trip | G130: 63.62 | H130: =E130*G130 | I130: ZESA | J130: EcoCash | M130: S04
A131: 2026-01-29 | B131: shared | C131: Fuel | D131: Diesel - generator/vehicle | E131: 45 | F131: litre | G131: 1.62 | H131: =E131*G131 | I131: Puma Energy Goromonzi | J131: Cash | M131: S04
A132: 2026-01-29 | B132: shared | C132: Electricity | D132: ZESA prepaid token | E132: 1 | F132: trip | G132: 70.97 | H132: =E132*G132 | I132: ZESA | J132: EcoCash | M132: S04
A133: 2026-02-28 | B133: shared | C133: Fuel | D133: Diesel - generator/vehicle | E133: 40 | F133: litre | G133: 1.61 | H133: =E133*G133 | I133: Puma Energy Goromonzi | J133: Cash | M133: S04
...

Sheet 03_REVENUE
A1: PURPOSE: Single money-in ledger; per-domain sales all use identical columns. | CADENCE: Every sale | ENTERED BY: Owner / sales clerk
A2: date | B2: domain | C2: product | D2: quantity | E2: unit | F2: unit_price | G2: total_amount | H2: head_count | I2: avg_weight_kg | J2: grade | K2: buyer | L2: channel | M2: payment_status | N2: batch_ref
A3: 2026-09-03 | B3: poultry | C3: Dressed chicken | D3: 48 | E3: head | F3: 6.2 | G3: =D3*F3 | H3: 48 | I3: 2.1 | K3: Local market vendor | L3: Market | M3: Paid | N3: BRO-24
A4: 2026-02-18 | B4: piggery | C4: Live pig | D4: 760 | E4: kg | F4: 1.79 | G4: =D4*F4 | H4: 10 | I4: 76 | K4: Colcom Abattoir | L4: Abattoir | M4: Paid | N4: PIG-B01
A5: 2026-08-17 | B5: piggery | C5: Live pig | D5: 2233 | E5: kg | F5: 1.82 | G5: =D5*F5 | H5: 22 | I5: 101.5 | K5: Colcom Abattoir | L5: Abattoir | M5: Paid | N5: PIG-B02
A6: 2026-03-20 | B6: piggery | C6: Live pig | D6: 2014.8 | E6: kg | F6: 1.94 | G6: =D6*F6 | H6: 23 | I6: 87.6 | K6: Colcom Abattoir | L6: Abattoir | M6: Paid | N6: PIG-B03
A7: 2025-11-21 | B7: poultry | C7: Live broiler | D7: 497 | E7: head | F7: 6.36 | G7: =D7*F7 | H7: 497 | I7: 2.1 | K7: Local market vendor | L7: Market | M7: Paid | N7: BRO-P01
A8: 2026-01-31 | B8: poultry | C8: Live broiler | D8: 478 | E8: head | F8: 5.98 | G8: =D8*F8 | H8: 478 | I8: 1.9 | K8: Local market vendor | L8: Market | M8: Paid | N8: BRO-P02
A9: 2026-04-16 | B9: poultry | C9: Live broiler | D9: 500 | E9: head | F9: 6.28 | G9: =D9*F9 | H9: 500 | I9: 2.1 | K9: Greenline Butchery (30-day account) | L9: Contract | M9: Paid | N9: BRO-P03
A10: 2026-04-12 | B10: crops | C10: Maize grain | D10: 710 | E10: bag | F10: 13.32 | G10: =D10*F10 | J10: A | K10: Mbare Musika trader | L10: Market | M10: Paid | N10: MZ-PL1-25A
A11: 2026-03-28 | B11: crops | C11: Soya | D11: 368 | E11: bag | F11: 23.59 | G11: =D11*F11 | J11: A | K11: Chikafu Grain Traders | L11: Contract | M11: Owing | N11: SB-PL2-25A
A12: 2026-04-22 | B12: crops | C12: Maize grain | D12: 137 | E12: bag | F12: 28.6 | G12: =D12*F12 | J12: B | K12: Mbare Musika trader | L12: Market | M12: Paid | N12: GN-PL3-25A
A13: 2026-08-18 | B13: crops | C13: Tomatoes | D13: 2262 | E13: crate | F13: 8.34 | G13: =D13*F13 | J13: B | K13: Mbare Musika trader | L13: Market | M13: Paid | N13: TM-PL1-26A

Sheet 04_LABOUR_LOG
A1: PURPOSE: Answers 'which enterprise eats my wage bill' and cost per kg produced. | CADENCE: Daily, one row per worker per domain | ENTERED BY: Supervisor at end of shift
A2: date | B2: staff_code | C2: domain | D2: task | E2: hours | F2: overtime_hours | G2: labour_cost | H2: batch_ref
A3: 2026-09-01 | B3: S01 | C3: piggery | D3: Feeding | E3: 8 | F3: 0 | G3: =IFERROR(INDEX('01_STAFF'!$F:$F,MATCH(B3,'01_STAFF'!$A:$A,0))*E3,0)
A4: 2025-10-01 | B4: S01 | C4: piggery | D4: Cleaning | E4: 8 | F4: 0 | G4: =IFERROR(INDEX('01_STAFF'!$F:$F,MATCH(B4,'01_STAFF'!$A:$A,0))*E4,0)
A5: 2025-10-01 | B5: S02 | C5: poultry | D5: Vaccination | E5: 8 | F5: 0 | G5: =IFERROR(INDEX('01_STAFF'!$F:$F,MATCH(B5,'01_STAFF'!$A:$A,0))*E5,0)
A6: 2025-10-01 | B6: S03 | C6: crops | D6: Maintenance | E6: 8 | F6: 0 | G6: =IFERROR(INDEX('01_STAFF'!$F:$F,MATCH(B6,'01_STAFF'!$A:$A,0))*E6,0)
A7: 2025-10-01 | B7: S04 | C7: shared | D7: Weighing | E7: 7 | F7: 0 | G7: =IFERROR(INDEX('01_STAFF'!$F:$F,MATCH(B7,'01_STAFF'!$A:$A,0))*E7,0)
A8: 2025-10-02 | B8: S01 | C8: piggery | D8: Vaccination | E8: 8 | F8: 0 | G8: =IFERROR(INDEX('01_STAFF'!$F:$F,MATCH(B8,'01_STAFF'!$A:$A,0))*E8,0)
A9: 2025-10-02 | B9: S02 | C9: poultry | D9: Vaccination | E9: 8 | F9: 0 | G9: =IFERROR(INDEX('01_STAFF'!$F:$F,MATCH(B9,'01_STAFF'!$A:$A,0))*E9,0)
A10: 2025-10-02 | B10: S03 | C10: crops | D10: Maintenance | E10: 8 | F10: 0 | G10: =IFERROR(INDEX('01_STAFF'!$F:$F,MATCH(B10,'01_STAFF'!$A:$A,0))*E10,0)
A11: 2025-10-02 | B11: S04 | C11: shared | D11: Vaccination | E11: 6 | F11: 0 | G11: =IFERROR(INDEX('01_STAFF'!$F:$F,MATCH(B11,'01_STAFF'!$A:$A,0))*E11,0)
A12: 2025-10-03 | B12: S01 | C12: piggery | D12: Weighing | E12: 8 | F12: 0 | G12: =IFERROR(INDEX('01_STAFF'!$F:$F,MATCH(B12,'01_STAFF'!$A:$A,0))*E12,0)
A13: 2025-10-03 | B13: S02 | C13: poultry | D13: Cleaning | E13: 8 | F13: 0 | G13: =IFERROR(INDEX('01_STAFF'!$F:$F,MATCH(B13,'01_STAFF'!$A:$A,0))*E13,0)
A14: 2025-10-03 | B14: S03 | C14: crops | D14: Spraying | E14: 8 | F14: 0 | G14: =IFERROR(INDEX('01_STAFF'!$F:$F,MATCH(B14,'01_STAFF'!$A:$A,0))*E14,0)
... A1146: 2026-09-15 | B1146: S04 | C1146: shared | D1146: Maintenance | E1146: 6 | F1146: 0 | G1146: =IFERROR(INDEX('01_STAFF'!$F:$F,MATCH(B1146,'01_STAFF'!$A:$A,0))*E1146,0)

Sheet 05_WEATHER_LOG
A1: PURPOSE: Cross-domain explanatory variable: heat stress in poultry houses, rainfall vs crop stage, feed intake dips in pigs. | CADENCE: Daily, 30 seconds | ENTERED BY: Whoever opens the gate in the morning
A2: date | B2: rainfall_mm | C2: temp_min_c | D2: temp_max_c | E2: humidity_pct | F2: event
A3: 2026-09-01 | B3: 0 | C3: 14 | D3: 27 | E3: 48 | F3: Normal
A4: 2025-10-01 | B4: 0 | C4: 6.5 | D4: 23.6 | E4: 39 | F4: Normal
A5: 2025-10-02 | B5: 0 | C5: 8.8 | D5: 21.7 | E5: 44 | F5: Normal
A6: 2025-10-03 | B6: 0 | C6: 6.7 | D6: 24.8 | E6: 41 | F6: Normal
A7: 2025-10-04 | B7: 0 | C7: 7.1 | D7: 20.8 | E7: 42 | F7: Normal
A8: 2025-10-05 | B8: 0 | C8: 7 | D8: 20.8 | E8: 44 | F8: Normal
A9: 2025-10-06 | B9: 0 | C9: 7.1 | D9: 23.2 | E9: 43 | F9: Normal
A10: 2025-10-07 | B10: 0 | C10: 6.4 | D10: 24.4 | E10: 46 | F10: Normal
A11: 2025-10-08 | B11: 0 | C11: 7.5 | D11: 23.9 | E11: 38 | F11: Normal
A12: 2025-10-09 | B12: 0 | C12: 7.5 | D12: 25.1 | E12: 37 | F12: Normal
A13: 2025-10-10 | B13: 0 | C13: 9.1 | D13: 21.1 | E13: 43 | F13: Normal
A14: 2025-10-11 | B14: 0 | C14: 8.7 | D14: 24.4 | E14: 42 | F14: Normal
... A353: 2026-09-15 | B353: 0 | C353: 6.7 | D353: 21 | E353: 47 | F353: Normal

Sheet 06_FEED_INVENTORY
A1: PURPOSE: THE cross-domain sheet. Pigs and chickens draw from the same store, so this is where 'feed cost split between pigs and chickens' is actually answered accurately. | CADENCE: Weekly stock count (+ every delivery) | ENTERED BY: Store keeper
A2: date | B2: domain | C2: feed_type | D2: opening_kg | E2: received_kg | F2: used_kg | G2: waste_kg | H2: closing_kg | I2: unit_cost_per_kg | J2: supplier | K2: batch_ref
A3: 2026-09-07 | B3: piggery | C3: Pig grower | D3: 1200 | E3: 500 | F3: 430 | G3: 5 | H3: 1265 | I3: 0.68 | J3: Profeeds Marondera
A4: 2025-10-27 | B4: piggery | C4: Pig grower | D4: 400 | E4: 240 | F4: 3.7 | G4: 0 | H4: 636.3 | I4: 0.68 | J4: Profeeds Marondera
A5: 2025-11-03 | B5: piggery | C5: Pig grower | D5: 636.3 | E5: 237 | F5: 30.4 | G5: 0.4 | H5: 842.5 | I5: 0.68 | J5: Profeeds Marondera
A6: 2025-11-10 | B6: piggery | C6: Pig grower | D6: 842.5 | E6: 239 | F6: 109.1 | G6: 1.3 | H6: 971.1 | I6: 0.68 | J6: Profeeds Marondera
A7: 2025-11-17 | B7: piggery | C7: Pig grower | D7: 971.1 | E7: 256 | F7: 143 | G7: 1.7 | H7: 1082.4 | I7: 0.68 | J7: Profeeds Marondera
A8: 2025-11-24 | B8: piggery | C8: Pig grower | D8: 1082.4 | E8: 232 | F8: 178.6 | G8: 2.1 | H8: 1133.7 | I8: 0.68 | J8: Profeeds Marondera
A9: 2025-12-01 | B9: piggery | C9: Pig grower | D9: 1133.7 | E9: 267 | F9: 214.7 | G9: 2.6 | H9: 1183.4 | I9: 0.68 | J9: Profeeds Marondera
A10: 2025-12-08 | B10: piggery | C10: Pig grower | D10: 1183.4 | E10: 254 | F10: 244.3 | G10: 2.9 | H10: 1190.2 | I10: 0.68 | J10: Profeeds Marondera
A11: 2025-12-15 | B11: piggery | C11: Pig grower | D11: 1190.2 | E11: 334 | F11: 280.9 | G11: 3.4 | H11: 1239.9 | I11: 0.68 | J11: Profeeds Marondera
A12: 2025-12-22 | B12: piggery | C12: Pig grower | D12: 1239.9 | E12: 371 | F12: 301.1 | G12: 3.6 | H12: 1306.2 | I12: 0.68 | J12: Profeeds Marondera
A13: 2025-12-29 | B13: piggery | C13: Pig grower | D13: 1306.2 | E13: 371 | F13: 334.7 | G13: 4 | H13: 1338.5 | I13: 0.68 | J13: Profeeds Marondera
A14: 2026-01-05 | B14: piggery | C14: Pig grower | D14: 1338.5 | E14: 433 | F14: 378.1 | G14: 4.5 | H14: 1388.9 | I14: 0.68 | J14: Profeeds Marondera
... A78: 2026-09-14 | B78: poultry | C78: Broiler grower | D78: 1920.7 | E78: 185 | F78: 130.7 | G78: 2 | H78: 1973 | I78: 0.74 | J78: Profeeds Marondera

Sheet 07_HEALTH_LOG
A1: PURPOSE: Unified livestock health ledger for pigs AND poultry — one shape, two domains, so disease-cost questions work across the farm. | CADENCE: Per event (treatment / vaccination) | ENTERED BY: Attendant or visiting vet
A2: date | B2: domain | C2: batch_ref | D2: animal_tag | E2: event_type | F2: symptom | G2: diagnosis | H2: product | I2: dose | J2: animals_treated | K2: cost | L2: withdrawal_until | M2: outcome | N2: administered_by
A3: 2026-08-20 | B3: poultry | C3: BRO-24 | E3: Vaccination | F3: None | H3: Newcastle LaSota | I3: 1 drop/bird | J3: 500 | K3: 18 | M3: Ongoing | N3: S02
A4: 2026-04-25 | B4: piggery | C4: PIG-B02 | E4: Inspection | F4: Diarrhoea | G4: Suspected bacterial enteritis / respiratory complex | J4: 26 | K4: 15 | M4: Ongoing | N4: S01
A5: 2026-04-27 | B5: piggery | C5: PIG-B02 | E5: Treatment | F5: Off-feed | G5: Bacterial enteritis / respiratory complex | H5: Oxytetracycline LA | I5: 1ml/10kg IM | J5: 6 | K5: 34.98 | L5: 2026-05-18 | M5: Died | N5: S01
A6: 2026-04-29 | B6: piggery | C6: PIG-B02 | E6: Treatment | F6: Off-feed | G6: Bacterial enteritis / respiratory complex | H6: Oxytetracycline LA | I6: 1ml/10kg IM | J6: 7 | K6: 40.47 | L6: 2026-05-20 | M6: Died | N6: S01
A7: 2026-05-01 | B7: piggery | C7: PIG-B02 | E7: Treatment | F7: Coughing | G7: Bacterial enteritis / respiratory complex | H7: Oxytetracycline LA | I7: 1ml/10kg IM | J7: 8 | K7: 36.77 | L7: 2026-05-22 | M7: Ongoing | N7: S01
A8: 2026-05-05 | B8: piggery | C8: PIG-B02 | E8: Treatment | F8: Diarrhoea | G8: Bacterial enteritis / respiratory complex | H8: Oxytetracycline LA | I8: 1ml/10kg IM | J8: 14 | K8: 41.33 | L8: 2026-05-26 | M8: Recovered | N8: S01
A9: 2025-11-09 | B9: piggery | C9: PIG-B01 | E9: Vaccination | F9: None | H9: Erysipelas + Parvo combo | I9: 2ml IM | J9: 10 | K9: 9 | M9: Recovered | N9: S01
A10: 2026-03-09 | B10: piggery | C10: PIG-B02 | E10: Vaccination | F10: None | H10: Erysipelas + Parvo combo | I10: 2ml IM | J10: 26 | K10: 23.4 | M10: Recovered | N10: S01
A11: 2025-11-17 | B11: piggery | C11: PIG-B03 | E11: Vaccination | F11: None | H11: Erysipelas + Parvo combo | I11: 2ml IM | J11: 24 | K11: 21.6 | M11: Recovered | N11: S01
A12: 2026-05-19 | B12: piggery | C12: PIG-B04 | E12: Vaccination | F12: None | H12: Erysipelas + Parvo combo | I12: 2ml IM | J12: 12 | K12: 10.8 | M12: Recovered | N12: S01
A13: 2026-01-10 | B13: poultry | C13: BRO-P02 | E13: Inspection | F13: Off-feed | G13: Heat stress | J13: 520 | K13: 0 | M13: Ongoing | N13: S02
A14: 2025-10-17 | B14: poultry | C14: BRO-P01 | E14: Vaccination | F14: None | H14: Newcastle LaSota | I14: 1 drop/bird | J14: 500 | K14: 17.5 | M14: Ongoing | N14: S02
A15: 2025-12-27 | B15: poultry | C15: BRO-P02 | E15: Vaccination | F15: None | H15: Newcastle LaSota | I15: 1 drop/bird | J15: 520 | K15: 18.2 | M15: Ongoing | N15: S02
A16: 2026-03-12 | B16: poultry | C16: BRO-P03 | E16: Vaccination | F16: None | H16: Newcastle LaSota | I16: 1 drop/bird | J16: 500 | K16: 17.5 | M16: Ongoing | N16: S02
A17: 2026-08-11 | B17: poultry | C17: BRO-P04 | E17: Vaccination | F17: None | H17: Newcastle LaSota | I17: 1 drop/bird | J17: 510 | K17: 17.85 | M17: Ongoing | N17: S02

Sheet P1_PIG_BATCHES
A1: PURPOSE: Batch register — the anchor every piggery row points at. | CADENCE: On batch creation | ENTERED BY: Supervisor
A2: batch_code | B2: pen | C2: breed | D2: start_date | E2: start_count | F2: start_avg_kg | G2: source | H2: target_market_date | I2: status
A3: PIG-B07 | B3: Pen 3 | C3: Large White | D3: 2026-06-01 | E3: 24 | F3: 8.5 | G3: Own farrowing | H3: 2026-10-15 | I3: Active
A4: PIG-B01 | B4: Pen 1 | C4: Large White | D4: 2025-11-02 | E4: 10 | F4: 7 | G4: Own farrowing | H4: 2026-02-22 | I4: Sold
A5: PIG-B02 | B5: Pen 1 | C5: Duroc cross | D5: 2026-03-02 | E5: 26 | F5: 9 | G5: Bought-in | H5: 2026-08-15 | I5: Sold
A6: PIG-B03 | B6: Pen 2 | C6: Landrace | D6: 2025-11-10 | E6: 24 | F6: 8.2 | G6: Bought-in | H6: 2026-03-20 | I6: Sold
A7: PIG-B04 | B7: Pen 2 | C7: Duroc cross | D7: 2026-05-12 | E7: 12 | F7: 7.2 | G7: Own farrowing | H7: 2026-09-20 | I7: Active

Sheet P2_PIG_DAILY_LOG
A1: PURPOSE: Feed, water, mortality, headcount. The engine of FCR, ADG and mortality analytics. | CADENCE: Daily, one row per pen | ENTERED BY: Pig attendant
A2: date | B2: batch_code | C2: pen | D2: feed_type | E2: feed_kg | F2: water_litres | G2: deaths | H2: culls | I2: closing_count | J2: pen_temp_c | K2: pen_condition | L2: notes | M2: recorded_by
A3: 2026-09-01 | B3: PIG-B07 | C3: Pen 3 | D3: Pig grower | E3: 42 | F3: 110 | G3: 0 | H3: 0 | I3: =IFERROR(INDEX(P1_PIG_BATCHES!$E:$E,MATCH(B3,P1_PIG_BATCHES!$A:$A,0))-G3-H3,0) | J3: 24 | K3: Dry | M3: S01
A4: 2025-11-02 | B4: PIG-B01 | C4: Pen 1 | D4: Pig starter | E4: 3.7 | F4: 9.6 | G4: 0 | H4: 0 | I4: =IFERROR(INDEX(P1_PIG_BATCHES!$E:$E,MATCH(B4,P1_PIG_BATCHES!$A:$A,0))-G4-H4,0) | J4: 21.6 | K4: Dry | M4: S01
A5: 2025-11-03 | B5: PIG-B01 | C5: Pen 1 | D5: Pig starter | E5: 3.7 | F5: 9.4 | G5: 0 | H5: 0 | I5: =IFERROR(INDEX(P1_PIG_BATCHES!$E:$E,MATCH(B5,P1_PIG_BATCHES!$A:$A,0))-G5-H5,0) | J5: 24.2 | K5: Dry | M5: S01
A6: 2025-11-04 | B6: PIG-B01 | C6: Pen 1 | D6: Pig starter | E6: 3.8 | F6: 9.2 | G6: 0 | H6: 0 | I6: =IFERROR(INDEX(P1_PIG_BATCHES!$E:$E,MATCH(B6,P1_PIG_BATCHES!$A:$A,0))-G6-H6,0) | J6: 23.3 | K6: Dry | M6: S01
A7: 2025-11-05 | B7: PIG-B01 | C7: Pen 1 | D7: Pig starter | E7: 4.2 | F7: 11.9 | G7: 0 | H7: 0 | I7: =IFERROR(INDEX(P1_PIG_BATCHES!$E:$E,MATCH(B7,P1_PIG_BATCHES!$A:$A,0))-G7-H7,0) | J7: 25.1 | K7: Dry | M7: S01
A8: 2025-11-06 | B8: PIG-B01 | C8: Pen 1 | D8: Pig starter | E8: 3.9 | F8: 10.7 | G8: 0 | H8: 0 | I8: =IFERROR(INDEX(P1_PIG_BATCHES!$E:$E,MATCH(B8,P1_PIG_BATCHES!$A:$A,0))-G8-H8,0) | J8: 22.4 | K8: Dry | M8: S01
A9: 2025-11-07 | B9: PIG-B01 | C9: Pen 1 | D9: Pig starter | E9: 4.7 | F9: 13.7 | G9: 0 | H9: 0 | I9: =IFERROR(INDEX(P1_PIG_BATCHES!$E:$E,MATCH(B9,P1_PIG_BATCHES!$A:$A,0))-G9-H9,0) | J9: 26.7 | K9: Dry | M9: S01
A10: 2025-11-08 | B10: PIG-B01 | C10: Pen 1 | D10: Pig starter | E10: 4.9 | F10: 11.4 | G10: 0 | H10: 0 | I10: =IFERROR(INDEX(P1_PIG_BATCHES!$E:$E,MATCH(B10,P1_PIG_BATCHES!$A:$A,0))-G10-H10,0) | J10: 22.9 | K10: Dry | M10: S01
A11: 2025-11-09 | B11: PIG-B01 | C11: Pen 1 | D11: Pig starter | E11: 5.2 | F11: 13.1 | G11: 0 | H11: 0 | I11: =IFERROR(INDEX(P1_PIG_BATCHES!$E:$E,MATCH(B11,P1_PIG_BATCHES!$A:$A,0))-G11-H11,0) | J11: 24.7 | K11: Dry | M11: S01
A12: 2025-11-10 | B12: PIG-B01 | C12: Pen 1 | D12: Pig starter | E12: 4.9 | F12: 12.3 | G12: 0 | H12: 0 | I12: =IFERROR(INDEX(P1_PIG_BATCHES!$E:$E,MATCH(B12,P1_PIG_BATCHES!$A:$A,0))-G12-H12,0) | J12: 26.1 | K12: Dry | M12: S01
A13: 2025-11-11 | B13: PIG-B01 | C13: Pen 1 | D13: Pig starter | E13: 5.6 | F13: 16 | G13: 0 | H13: 0 | I13: =IFERROR(INDEX(P1_PIG_BATCHES!$E:$E,MATCH(B13,P1_PIG_BATCHES!$A:$A,0))-G13-H13,0) | J13: 25.7 | K13: Dry | M13: S01
A14: 2025-11-12 | B14: PIG-B01 | C14: Pen 1 | D14: Pig starter | E14: 5.6 | F14: 15.2 | G14: 0 | H14: 0 | I14: =IFERROR(INDEX(P1_PIG_BATCHES!$E:$E,MATCH(B14,P1_PIG_BATCHES!$A:$A,0))-G14-H14,0) | J14: 23.4 | K14: Dry | M14: S01
... A166: 2026-04-24 | B166: PIG-B02 | C166: Pen 1 | D166: Pig grower | E166: 36.5 | F166: 95.5 | G166: 0 | H166: 0 | I166: =IFERROR(INDEX(P1_PIG_BATCHES!$E:$E,MATCH(B166,P1_PIG_BATCHES!$A:$A,0))-G166-H166,0) | J166: 21.2 | K166: Dry | M166: S01
A167: 2026-04-25 | B167: PIG-B02 | C167: Pen 1 | D167: Pig grower | E167: 22.7 | F167: 51.8 | G167: 1 | H167: 0 | I167: =IFERROR(INDEX(P1_PIG_BATCHES!$E:$E,MATCH(B167,P1_PIG_BATCHES!$A:$A,0))-G167-H167,0) | J167: 24.1 | K167: Damp | L167: Several pigs off-feed, loose stools - vet called | M167: S01
A168: 2026-04-26 | B168: PIG-B02 | C168: Pen 1 | D168: Pig grower | E168: 22.3 | F168: 58.2 | G168: 0 | H168: 0 | I168: =IFERROR(INDEX(P1_PIG_BATCHES!$E:$E,MATCH(B168,P1_PIG_BATCHES!$A:$A,0))-G168-H168,0) | J168: 23.7 | K168: Damp | M168: S01
A169: 2026-04-27 | B169: PIG-B02 | C169: Pen 1 | D169: Pig grower | E169: 21.8 | F169: 61.9 | G169: 1 | H169: 0 | I169: =IFERROR(INDEX(P1_PIG_BATCHES!$E:$E,MATCH(B169,P1_PIG_BATCHES!$A:$A,0))-G169-H169,0) | J169: 25.6 | K169: Damp | M169: S01
A170: 2026-04-28 | B170: PIG-B02 | C170: Pen 1 | D170: Pig grower | E170: 24 | F170: 67 | G170: 0 | H170: 0 | I170: =IFERROR(INDEX(P1_PIG_BATCHES!$E:$E,MATCH(B170,P1_PIG_BATCHES!$A:$A,0))-G170-H170,0) | J170: 24.6 | K170: Damp | M170: S01
A171: 2026-04-29 | B171: PIG-B02 | C171: Pen 1 | D171: Pig grower | E171: 20.8 | F171: 47 | G171: 1 | H171: 0 | I171: =IFERROR(INDEX(P1_PIG_BATCHES!$E:$E,MATCH(B171,P1_PIG_BATCHES!$A:$A,0))-G171-H171,0) | J171: 27.6 | K171: Damp | M171: S01
A172: 2026-04-30 | B172: PIG-B02 | C172: Pen 1 | D172: Pig grower | E172: 19.7 | F172: 57.9 | G172: 0 | H172: 0 | I172: =IFERROR(INDEX(P1_PIG_BATCHES!$E:$E,MATCH(B172,P1_PIG_BATCHES!$A:$A,0))-G172-H172,0) | J172: 20.6 | K172: Damp | M172: S01
A173: 2026-05-01 | B173: PIG-B02 | C173: Pen 1 | D173: Pig grower | E173: 23.7 | F173: 66.5 | G173: 0 | H173: 0 | I173: =IFERROR(INDEX(P1_PIG_BATCHES!$E:$E,MATCH(B173,P1_PIG_BATCHES!$A:$A,0))-G173-H173,0) | J173: 27.4 | K173: Damp | M173: S01
A174: 2026-05-02 | B174: PIG-B02 | C174: Pen 1 | D174: Pig grower | E174: 22.1 | F174: 66 | G174: 0 | H174: 0 | I174: =IFERROR(INDEX(P1_PIG_BATCHES!$E:$E,MATCH(B174,P1_PIG_BATCHES!$A:$A,0))-G174-H174,0) | J174: 23.2 | K174: Damp | M174: S01
A175: 2026-05-03 | B175: PIG-B02 | C175: Pen 1 | D175: Pig grower | E175: 25 | F175: 62.6 | G175: 0 | H175: 0 | I175: =IFERROR(INDEX(P1_PIG_BATCHES!$E:$E,MATCH(B175,P1_PIG_BATCHES!$A:$A,0))-G175-H175,0) | J175: 25.3 | K175: Damp | M175: S01
A176: 2026-05-04 | B176: PIG-B02 | C176: Pen 1 | D176: Pig grower | E176: 23.3 | F176: 63.4 | G176: 0 | H176: 0 | I176: =IFERROR(INDEX(P1_PIG_BATCHES!$E:$E,MATCH(B176,P1_PIG_BATCHES!$A:$A,0))-G176-H176,0) | J176: 22.9 | K176: Damp | M176: S01
A177: 2026-05-05 | B177: PIG-B02 | C177: Pen 1 | D177: Pig grower | E177: 22.6 | F177: 59.3 | G177: 1 | H177: 0 | I177: =IFERROR(INDEX(P1_PIG_BATCHES!$E:$E,MATCH(B177,P1_PIG_BATCHES!$A:$A,0))-G177-H177,0) | J177: 25.6 | K177: Damp | M177: S01
A178: 2026-05-06 | B178: PIG-B02 | C178: Pen 1 | D178: Pig grower | E178: 33.2 | F178: 74 | G178: 0 | H178: 0 | I178: =IFERROR(INDEX(P1_PIG_BATCHES!$E:$E,MATCH(B178,P1_PIG_BATCHES!$A:$A,0))-G178-H178,0) | J178: 22.5 | K178: Dry | M178: S01
A179: 2026-05-07 | B179: PIG-B02 | C179: Pen 1 | D179: Pig grower | E179: 38.6 | F179: 101.3 | G179: 0 | H179: 0 | I179: =IFERROR(INDEX(P1_PIG_BATCHES!$E:$E,MATCH(B179,P1_PIG_BATCHES!$A:$A,0))-G179-H179,0) | J179: 26.3 | K179: Dry | M179: S01
... A532: 2026-09-15 | B532: PIG-B04 | C532: Pen 2 | D532: Pig finisher | E532: 30 | F532: 77.4 | G532: 0 | H532: 0 | I532: =IFERROR(INDEX(P1_PIG_BATCHES!$E:$E,MATCH(B532,P1_PIG_BATCHES!$A:$A,0))-G532-H532,0) | J532: 21.5 | K532: Dry | M532: S01

Sheet P3_PIG_WEIGHTS
A1: PURPOSE: Growth curve, ADG, days-to-market projection. | CADENCE: Fortnightly sample weighing | ENTERED BY: Attendant + supervisor
A2: date | B2: batch_code | C2: sample_size | D2: avg_weight_kg | E2: min_weight_kg | F2: max_weight_kg | G2: age_days
A3: 2026-09-01 | B3: PIG-B07 | C3: 10 | D3: 38.2 | E3: 31 | F3: 44 | G3: =IFERROR(A3-INDEX(P1_PIG_BATCHES!$D:$D,MATCH(B3,P1_PIG_BATCHES!$A:$A,0)),"")
A4: 2025-11-16 | B4: PIG-B01 | C4: 10 | D4: 15 | E4: 12.3 | F4: 17.7 | G4: =IFERROR(A4-INDEX(P1_PIG_BATCHES!$D:$D,MATCH(B4,P1_PIG_BATCHES!$A:$A,0)),"")
A5: 2025-11-30 | B5: PIG-B01 | C5: 10 | D5: 23.2 | E5: 19 | F5: 27.4 | G5: =IFERROR(A5-INDEX(P1_PIG_BATCHES!$D:$D,MATCH(B5,P1_PIG_BATCHES!$A:$A,0)),"")
A6: 2025-12-14 | B6: PIG-B01 | C6: 10 | D6: 31.5 | E6: 25.8 | F6: 37.2 | G6: =IFERROR(A6-INDEX(P1_PIG_BATCHES!$D:$D,MATCH(B6,P1_PIG_BATCHES!$A:$A,0)),"")
A7: 2025-12-28 | B7: PIG-B01 | C7: 10 | D7: 40.2 | E7: 33 | F7: 47.4 | G7: =IFERROR(A7-INDEX(P1_PIG_BATCHES!$D:$D,MATCH(B7,P1_PIG_BATCHES!$A:$A,0)),"")
A8: 2026-01-11 | B8: PIG-B01 | C8: 10 | D8: 48.6 | E8: 39.9 | F8: 57.3 | G8: =IFERROR(A8-INDEX(P1_PIG_BATCHES!$D:$D,MATCH(B8,P1_PIG_BATCHES!$A:$A,0)),"")
A9: 2026-01-25 | B9: PIG-B01 | C9: 10 | D9: 57.4 | E9: 47.1 | F9: 67.7 | G9: =IFERROR(A9-INDEX(P1_PIG_BATCHES!$D:$D,MATCH(B9,P1_PIG_BATCHES!$A:$A,0)),"")
A10: 2026-02-08 | B10: PIG-B01 | C10: 10 | D10: 67.9 | E10: 55.7 | F10: 80.1 | G10: =IFERROR(A10-INDEX(P1_PIG_BATCHES!$D:$D,MATCH(B10,P1_PIG_BATCHES!$A:$A,0)),"")
A11: 2026-03-16 | B11: PIG-B02 | C11: 10 | D11: 17 | E11: 13.9 | F11: 20.1 | G11: =IFERROR(A11-INDEX(P1_PIG_BATCHES!$D:$D,MATCH(B11,P1_PIG_BATCHES!$A:$A,0)),"")
A12: 2026-03-30 | B12: PIG-B02 | C12: 10 | D12: 27 | E12: 22.1 | F12: 31.9 | G12: =IFERROR(A12-INDEX(P1_PIG_BATCHES!$D:$D,MATCH(B12,P1_PIG_BATCHES!$A:$A,0)),"")
A13: 2026-04-13 | B13: PIG-B02 | C13: 10 | D13: 34.2 | E13: 28 | F13: 40.4 | G13: =IFERROR(A13-INDEX(P1_PIG_BATCHES!$D:$D,MATCH(B13,P1_PIG_BATCHES!$A:$A,0)),"")
A14: 2026-04-27 | B14: PIG-B02 | C14: 10 | D14: 36.3 | E14: 29.8 | F14: 42.8 | G14: =IFERROR(A14-INDEX(P1_PIG_BATCHES!$D:$D,MATCH(B14,P1_PIG_BATCHES!$A:$A,0)),"")
... A40: 2026-09-15 | B40: PIG-B04 | C40: 10 | D40: 87.8 | E40: 72 | F40: 103.6 | G40: =IFERROR(A40-INDEX(P1_PIG_BATCHES!$D:$D,MATCH(B40,P1_PIG_BATCHES!$A:$A,0)),"")

Sheet P4_SOW_REGISTER
A1: PURPOSE: Breeding herd inventory. | CADENCE: On arrival / status change | ENTERED BY: Supervisor
A2: sow_tag | B2: breed | C2: date_of_birth | D2: parity | E2: body_condition_1_5 | F2: status
A3: SOW-12 | B3: Landrace | C3: 2024-03-10 | D3: 3 | E3: 3 | F3: Lactating
A4: SOW-01 | B4: Large White | C4: 2023-05-10 | D4: 2 | E4: 3 | F4: Open
A5: SOW-02 | B5: Landrace | C5: 2022-11-20 | D5: 4 | E5: 3 | F5: Pregnant
A6: SOW-03 | B6: Duroc cross | C6: 2023-08-15 | D6: 1 | E6: 4 | F6: Lactating

Sheet P5_BREEDING_FARROWING
A1: PURPOSE: Litters/sow/year, born-alive, pre-wean mortality, farrowing rate — the real profit drivers of a piggery. | CADENCE: Per service / per farrowing / per weaning (3 touches per row) | ENTERED BY: Supervisor
A2: sow_tag | B2: boar_tag | C2: service_date | D2: service_type | E2: pregnancy_confirmed | F2: expected_farrow_date | G2: farrow_date | H2: born_alive | I2: stillborn | J2: mummified | K2: avg_birth_weight_kg | L2: wean_date | M2: weaned_count | N2: avg_wean_weight_kg | O2: litter_batch_code
A3: SOW-12 | B3: BOAR-02 | C3: 2026-05-10 | D3: Natural | E3: Yes | F3: =C3+114
A4: SOW-01 | B4: BOAR-01 | C4: 2025-06-12 | D4: Natural | E4: Yes | F4: =C4+114 | G4: 2025-10-05 | H4: 11 | I4: 1 | J4: 0 | K4: 1.3 | L4: 2025-11-02 | M4: 10 | N4: 6.8 | O4: PIG-B01
A5: SOW-03 | B5: BOAR-02 | C5: 2025-12-20 | D5: AI | E5: Yes | F5: =C5+114 | G5: 2026-04-14 | H5: 13 | I5: 0 | J5: 1 | K5: 1.4 | L5: 2026-05-12 | M5: 12 | N5: 7.2 | O5: PIG-B04
A6: SOW-02 | B6: BOAR-01 | C6: 2026-07-20 | D6: Natural | E6: Yes | F6: =C6+114

Sheet C1_POULTRY_BATCHES
A1: PURPOSE: Flock register for broilers and layers. | CADENCE: On placement | ENTERED BY: Supervisor
A2: batch_code | B2: bird_type | C2: breed | D2: house | E2: placement_date | F2: chicks_placed | G2: chick_unit_cost | H2: hatchery | I2: target_off_date | J2: status
A3: BRO-24 | B3: Broiler | C3: Ross 308 | D3: House 2 | E3: 2026-08-10 | F3: 500 | G3: 0.55 | H3: Irvine's Zimbabwe | I3: 2026-09-21 | J3: Growing
A4: BRO-P01 | B4: Broiler | C4: Ross 308 | D4: House 1 | E4: 2025-10-10 | F4: 500 | G4: 0.55 | H4: Irvine's Zimbabwe | I4: 2025-11-21 | J4: Sold
A5: BRO-P02 | B5: Broiler | C5: Ross 308 | D5: House 1 | E5: 2025-12-20 | F5: 520 | G5: 0.58 | H5: Irvine's Zimbabwe | I5: 2026-01-31 | J5: Sold
A6: BRO-P03 | B6: Broiler | C6: Ross 308 | D6: House 1 | E6: 2026-03-05 | F6: 500 | G6: 0.55 | H6: Irvine's Zimbabwe | I6: 2026-04-16 | J6: Sold
A7: BRO-P04 | B7: Broiler | C7: Ross 308 | D7: House 1 | E7: 2026-08-04 | F7: 510 | G7: 0.6 | H7: National Foods Hatchery | I7: 2026-09-15 | J7: Growing

Sheet C2_POULTRY_DAILY_LOG
A1: PURPOSE: Mortality, feed, water, eggs, house climate. One sheet serves broilers and layers — egg columns simply stay 0 for broilers. | CADENCE: Daily, one row per house | ENTERED BY: Poultry attendant
A2: date | B2: batch_code | C2: age_days | D2: deaths | E2: culls | F2: closing_birds | G2: feed_type | H2: feed_kg | I2: water_litres | J2: house_temp_c | K2: litter_condition | L2: lighting_hours | M2: eggs_collected | N2: eggs_cracked | O2: eggs_dirty | P2: notes | Q2: recorded_by
A3: 2026-09-01 | B3: BRO-24 | C3: 22 | D3: 2 | E3: 0 | F3: 498 | G3: Broiler grower | H3: 58 | I3: 95 | J3: 29 | K3: Dry | M3: 0 | N3: 0 | O3: 0 | Q3: S02
A4: 2025-10-10 | B4: BRO-P01 | C4: 0 | D4: 0 | E4: 0 | F4: 500 | G4: Chick mash | H4: 10.5 | I4: 16.8 | J4: 33.2 | K4: Dry | L4: 23 | M4: 0 | N4: 0 | O4: 0 | Q4: S02
A5: 2025-10-11 | B5: BRO-P01 | C5: 1 | D5: 0 | E5: 0 | F5: 500 | G5: Chick mash | H5: 10.6 | I5: 18.4 | J5: 30.5 | K5: Dry | L5: 23 | M5: 0 | N5: 0 | O5: 0 | Q5: S02
A6: 2025-10-12 | B6: BRO-P01 | C6: 2 | D6: 0 | E6: 0 | F6: 500 | G6: Chick mash | H6: 13.6 | I6: 22.1 | J6: 32.7 | K6: Dry | L6: 23 | M6: 0 | N6: 0 | O6: 0 | Q6: S02
A7: 2025-10-13 | B7: BRO-P01 | C7: 3 | D7: 0 | E7: 0 | F7: 500 | G7: Chick mash | H7: 13.6 | I7: 27.2 | J7: 29.2 | K7: Dry | L7: 23 | M7: 0 | N7: 0 | O7: 0 | Q7: S02
A8: 2025-10-14 | B8: BRO-P01 | C8: 4 | D8: 0 | E8: 0 | F8: 500 | G8: Chick mash | H8: 16.3 | I8: 31.5 | J8: 31.4 | K8: Dry | L8: 23 | M8: 0 | N8: 0 | O8: 0 | Q8: S02
A9: 2025-10-15 | B9: BRO-P01 | C9: 5 | D9: 0 | E9: 0 | F9: 500 | G9: Chick mash | H9: 15.2 | I9: 28.6 | J9: 27.7 | K9: Dry | L9: 23 | M9: 0 | N9: 0 | O9: 0 | Q9: S02
A10: 2025-10-16 | B10: BRO-P01 | C10: 6 | D10: 0 | E10: 0 | F10: 500 | G10: Chick mash | H10: 17.5 | I10: 32.2 | J10: 32.1 | K10: Dry | L10: 23 | M10: 0 | N10: 0 | O10: 0 | Q10: S02
A11: 2025-10-17 | B11: BRO-P01 | C11: 7 | D11: 0 | E11: 0 | F11: 500 | G11: Chick mash | H11: 18.6 | I11: 32.3 | J11: 27.3 | K11: Dry | L11: 23 | M11: 0 | N11: 0 | O11: 0 | Q11: S02
A12: 2025-10-18 | B12: BRO-P01 | C12: 8 | D12: 0 | E12: 0 | F12: 500 | G12: Chick mash | H12: 22.3 | I12: 36.6 | J12: 32.6 | K12: Dry | L12: 23 | M12: 0 | N12: 0 | O12: 0 | Q12: S02
A13: 2025-10-19 | B13: BRO-P01 | C13: 9 | D13: 0 | E13: 0 | F13: 500 | G13: Chick mash | H13: 19.7 | I13: 33.4 | J13: 28.8 | K13: Dry | L13: 23 | M13: 0 | N13: 0 | O13: 0 | Q13: S02
A14: 2025-10-20 | B14: BRO-P01 | C14: 10 | D14: 0 | E14: 0 | F14: 500 | G14: Broiler starter | H14: 24.2 | I14: 44.4 | J14: 30.2 | K14: Dry | L14: 23 | M14: 0 | N14: 0 | O14: 0 | Q14: S02
A15: 2025-10-21 | B15: BRO-P01 | C15: 11 | D15: 0 | E15: 0 | F15: 500 | G15: Broiler starter | H15: 23.5 | I15: 42.5 | J15: 30.9 | K15: Dry | L15: 23 | M15: 0 | N15: 0 | O15: 0 | Q15: S02
... A25: 2025-10-31 | B25: BRO-P01 | C25: 21 | D25: 0 | E25: 0 | F25: 499 | G25: Broiler starter | H25: 36 | I25: 69 | J25: 26.5 | K25: Dry | L25: 23 | M25: 0 | N25: 0 | O25: 0 | Q25: S02
A26: 2025-11-01 | B26: BRO-P01 | C26: 22 | D26: 0 | E26: 0 | F26: 499 | G26: Broiler starter | H26: 38.2 | I26: 62.1 | J26: 26.8 | K26: Dry | M26: 0 | N26: 0 | O26: 0 | Q26: S02
A27: 2025-11-02 | B27: BRO-P01 | C27: 23 | D27: 2 | E27: 0 | F27: 497 | G27: Broiler starter | H27: 43.3 | I27: 74 | J27: 26.1 | K27: Dry | M27: 0 | N27: 0 | O27: 0 | Q27: S02
A28: 2025-11-03 | B28: BRO-P01 | C28: 24 | D28: 0 | E28: 0 | F28: 497 | G28: Broiler grower | H28: 38.2 | I28: 62.8 | J28: 27.1 | K28: Dry | M28: 0 | N28: 0 | O28: 0 | Q28: S02
A29: 2025-11-04 | B29: BRO-P01 | C29: 25 | D29: 0 | E29: 0 | F29: 497 | G29: Broiler grower | H29: 43.2 | I29: 71.9 | J29: 28.2 | K29: Dry | M29: 0 | N29: 0 | O29: 0 | Q29: S02
A30: 2025-11-05 | B30: BRO-P01 | C30: 26 | D30: 0 | E30: 0 | F30: 497 | G30: Broiler grower | H30: 46 | I30: 87.1 | J30: 24 | K30: Dry | M30: 0 | N30: 0 | O30: 0 | Q30: S02
A31: 2025-11-06 | B31: BRO-P01 | C31: 27 | D31: 0 | E31: 0 | F31: 497 | G31: Broiler grower | H31: 47.9 | I31: 88.1 | J31: 27.4 | K31: Dry | M31: 0 | N31: 0 | O31: 0 | Q31: S02
A32: 2025-11-07 | B32: BRO-P01 | C32: 28 | D32: 0 | E32: 0 | F32: 497 | G32: Broiler grower | H32: 50.3 | I32: 82.6 | J32: 26 | K32: Dry | M32: 0 | N32: 0 | O32: 0 | Q32: S02
A33: 2025-11-08 | B33: BRO-P01 | C33: 29 | D33: 0 | E33: 0 | F33: 497 | G33: Broiler grower | H33: 51.5 | I33: 100.2 | J33: 25.9 | K33: Dry | M33: 0 | N33: 0 | O33: 0 | Q33: S02
A34: 2025-11-09 | B34: BRO-P01 | C34: 30 | D34: 0 | E34: 0 | F34: 497 | G34: Broiler grower | H34: 45.6 | I34: 83.6 | J34: 27.2 | K34: Dry | M34: 0 | N34: 0 | O34: 0 | Q34: S02
A35: 2025-11-10 | B35: BRO-P01 | C35: 31 | D35: 0 | E35: 0 | F35: 497 | G35: Broiler grower | H35: 51 | I35: 100.2 | J35: 26 | K35: Dry | M35: 0 | N35: 0 | O35: 0 | Q35: S02
A36: 2025-11-11 | B36: BRO-P01 | C36: 32 | D36: 0 | E36: 0 | F36: 497 | G36: Broiler grower | H36: 55.6 | I36: 106.4 | J36: 24.8 | K36: Dry | M36: 0 | N36: 0 | O36: 0 | Q36: S02
A37: 2025-11-12 | B37: BRO-P01 | C37: 33 | D37: 0 | E37: 0 | F37: 497 | G37: Broiler grower | H37: 52.1 | I37: 85.5 | J37: 25.5 | K37: Dry | M37: 0 | N37: 0 | O37: 0 | Q37: S02
... A46: 2025-11-21 | B46: BRO-P01 | C46: 42 | D46: 0 | E46: 0 | F46: 497 | G46: Broiler finisher | H46: 67.5 | I46: 107.9 | J46: 27.6 | K46: Dry | M46: 0 | N46: 0 | O46: 0 | Q46: S02
A47: 2025-12-20 | B47: BRO-P02 | C47: 0 | D47: 0 | E47: 0 | F47: 520 | G47: Chick mash | H47: 11.2 | I47: 21.3 | J47: 33.3 | K47: Dry | L47: 23 | M47: 0 | N47: 0 | O47: 0 | Q47: S02
A48: 2025-12-21 | B48: BRO-P02 | C48: 1 | D48: 0 | E48: 0 | F48: 520 | G48: Chick mash | H48: 11.9 | I48: 20.1 | J48: 32.6 | K48: Dry | L48: 23 | M48: 0 | N48: 0 | O48: 0 | Q48: S02
A49: 2025-12-22 | B49: BRO-P02 | C49: 2 | D49: 0 | E49: 0 | F49: 520 | G49: Chick mash | H49: 12.5 | I49: 23.4 | J49: 33.4 | K49: Dry | L49: 23 | M49: 0 | N49: 0 | O49: 0 | Q49: S02
A50: 2025-12-23 | B50: BRO-P02 | C50: 3 | D50: 0 | E50: 0 | F50: 520 | G50: Chick mash | H50: 15.8 | I50: 31.7 | J50: 29.5 | K50: Dry | L50: 23 | M50: 0 | N50: 0 | O50: 0 | Q50: S02
A51: 2025-12-24 | B51: BRO-P02 | C51: 4 | D51: 0 | E51: 0 | F51: 520 | G51: Chick mash | H51: 14.3 | I51: 24.2 | J51: 31.3 | K51: Dry | L51: 23 | M51: 0 | N51: 0 | O51: 0 | Q51: S02
A52: 2025-12-25 | B52: BRO-P02 | C52: 5 | D52: 0 | E52: 0 | F52: 520 | G52: Chick mash | H52: 18.4 | I52: 35.7 | J52: 32.9 | K52: Dry | L52: 23 | M52: 0 | N52: 0 | O52: 0 | Q52: S02
A53: 2025-12-26 | B53: BRO-P02 | C53: 6 | D53: 0 | E53: 0 | F53: 520 | G53: Chick mash | H53: 19.5 | I53: 35.5 | J53: 30.9 | K53: Dry | L53: 23 | M53: 0 | N53: 0 | O53: 0 | Q53: S02
A54: 2025-12-27 | B54: BRO-P02 | C54: 7 | D54: 0 | E54: 0 | F54: 520 | G54: Chick mash | H54: 19 | I54: 31.6 | J54: 31.3 | K54: Dry | L54: 23 | M54: 0 | N54: 0 | O54: 0 | Q54: S02
A55: 2025-12-28 | B55: BRO-P02 | C55: 8 | D55: 0 | E55: 0 | F55: 520 | G55: Chick mash | H55: 21.3 | I55: 37.2 | J55: 29.6 | K55: Dry | L55: 23 | M55: 0 | N55: 0 | O55: 0 | Q55: S02
A56: 2025-12-29 | B56: BRO-P02 | C56: 9 | D56: 0 | E56: 0 | F56: 520 | G56: Chick mash | H56: 22.9 | I56: 38.8 | J56: 28.9 | K56: Dry | L56: 23 | M56: 0 | N56: 0 | O56: 0 | Q56: S02
A57: 2025-12-30 | B57: BRO-P02 | C57: 10 | D57: 0 | E57: 0 | F57: 520 | G57: Broiler starter | H57: 22.3 | I57: 38.4 | J57: 27.1 | K57: Dry | L57: 23 | M57: 0 | N57: 0 | O57: 0 | Q57: S02
...

Sheet C3_POULTRY_WEIGHTS
A1: PURPOSE: Weight-for-age vs breed standard, uniformity, FCR denominator. | CADENCE: Weekly (broilers) / monthly (layers) | ENTERED BY: Attendant
A2: date | B2: batch_code | C2: age_days | D2: sample_size | E2: avg_weight_g | F2: uniformity_pct
A3: 2026-09-01 | B3: BRO-24 | C3: 22 | D3: 25 | E3: 1180 | F3: 88
A4: 2025-10-17 | B4: BRO-P01 | C4: 7 | D4: 25 | E4: 370 | F4: 88
A5: 2025-10-24 | B5: BRO-P01 | C5: 14 | D5: 25 | E5: 703 | F5: 92
A6: 2025-10-31 | B6: BRO-P01 | C6: 21 | D6: 25 | E6: 992 | F6: 86
A7: 2025-11-07 | B7: BRO-P01 | C7: 28 | D7: 25 | E7: 1349 | F7: 84
A8: 2025-11-14 | B8: BRO-P01 | C8: 35 | D8: 25 | E8: 1584 | F8: 91
A9: 2025-11-21 | B9: BRO-P01 | C9: 42 | D9: 25 | E9: 1934 | F9: 89
A10: 2025-12-27 | B10: BRO-P02 | C10: 7 | D10: 25 | E10: 365 | F10: 81
A11: 2026-01-03 | B11: BRO-P02 | C11: 14 | D11: 25 | E11: 649 | F11: 75
A12: 2026-01-10 | B12: BRO-P02 | C12: 21 | D12: 25 | E12: 827 | F12: 76
A13: 2026-01-17 | B13: BRO-P02 | C13: 28 | D13: 25 | E13: 1101 | F13: 76
A14: 2026-01-24 | B14: BRO-P02 | C14: 35 | D14: 25 | E14: 1427 | F14: 76
... A27: 2026-09-15 | B27: BRO-P04 | C27: 42 | D27: 25 | E27: 2009 | F27: 92

Sheet F1_PLOTS
A1: PURPOSE: Land register; denominator of every per-hectare metric. | CADENCE: Once, updated rarely | ENTERED BY: Owner
A2: plot_code | B2: plot_name | C2: hectares | D2: soil_type | E2: irrigation_type | F2: gps
A3: P3 | B3: River field | C3: 6 | D3: Clay loam | E3: Sprinkler
A4: PL1 | B4: Home field | C4: 10 | D4: Clay loam | E4: Sprinkler
A5: PL2 | B5: Dam field | C5: 8 | D5: Sandy loam | E5: Rainfed
A6: PL3 | B6: Valley field | C6: 5 | D6: Red clay | E6: Drip

Sheet F2_PLANTINGS
A1: PURPOSE: Season x plot x crop anchor record — the crop equivalent of a batch. | CADENCE: Per planting event | ENTERED BY: Supervisor
A2: planting_code | B2: plot_code | C2: crop | D2: variety | E2: season | F2: planting_date | G2: area_ha | H2: seed_kg | I2: seed_cost | J2: expected_harvest_date | K2: expected_yield_tons_ha | L2: status
A3: MZ-P3-2025A | B3: P3 | C3: Maize | D3: SC637 | E3: 2025 Summer | F3: 2025-11-15 | G3: 6 | H3: 150 | I3: 210 | J3: 2026-04-15 | K3: 5.5 | L3: Growing
A4: MZ-PL1-25A | B4: PL1 | C4: Maize | D4: SC637 | E4: 2025 Summer | F4: 2025-11-20 | G4: 6 | H4: 150 | I4: 210 | J4: 2026-04-10 | K4: 5.5 | L4: Harvested
A5: SB-PL2-25A | B5: PL2 | C5: Soyabean | D5: SC Sequel | E5: 2025 Summer | F5: 2025-11-28 | G5: 8 | H5: 480 | I5: 960 | J5: 2026-03-25 | K5: 2.2 | L5: Harvested
A6: GN-PL3-25A | B6: PL3 | C6: Groundnuts | D6: Nyanda | E6: 2025 Summer | F6: 2025-12-02 | G6: 5 | H6: 300 | I6: 450 | J6: 2026-04-20 | K6: 1.5 | L6: Harvested
A7: TM-PL1-26A | B7: PL1 | C7: Tomatoes | D7: Roma VF | E7: 2026 Winter | F7: 2026-05-10 | G7: 2 | H7: 0.3 | I7: 180 | J7: 2026-08-15 | K7: 25 | L7: Harvested
A8: TM-PL2-26A | B8: PL2 | C8: Tomatoes | D8: Roma VF | E8: 2026 Winter | F8: 2026-06-01 | G8: 2 | H8: 0.3 | I8: 180 | J8: 2026-09-05 | K8: 25 | L8: Growing

Sheet F3_FIELD_OPERATIONS
A1: PURPOSE: Every input and pass over the field — the crop cost stack. | CADENCE: Per operation (a few rows per week per planting) | ENTERED BY: Field supervisor
A2: date | B2: planting_code | C2: op_type | D2: product | E2: rate | F2: quantity | G2: unit | H2: input_cost | I2: labour_hours | J2: machine_hours | K2: irrigation_mm | L2: notes | M2: recorded_by
A3: 2025-12-01 | B3: MZ-P3-2025A | C3: Top dressing | D3: AN | E3: 150 kg/ha | F3: 900 | G3: kg | H3: 540 | I3: 12 | J3: 2 | K3: 0 | M3: S03
A4: 2025-11-15 | B4: MZ-PL1-25A | C4: Land prep | G4: kg | H4: 199 | I4: 8 | J4: 3 | K4: 0 | M4: S03
A5: 2025-11-20 | B5: MZ-PL1-25A | C5: Planting | G5: kg | H5: 0 | I5: 6 | J5: 1 | K5: 0 | M5: S03
A6: 2025-12-15 | B6: MZ-PL1-25A | C6: Basal fert | D6: Compound D | E6: 300 kg/ha | F6: 1800 | G6: kg | H6: 518 | I6: 4 | J6: 1 | K6: 0 | M6: S03
A7: 2026-01-02 | B7: MZ-PL1-25A | C7: Top dressing | D7: AN | E7: 150 kg/ha | F7: 900 | G7: kg | H7: 371 | I7: 3 | J7: 1 | K7: 0 | M7: S03
A8: 2026-01-31 | B8: MZ-PL1-25A | C8: Herbicide | D8: Glyphosate | E8: 3 l/ha | F8: 18 | G8: litre | H8: 139 | I8: 3 | J8: 0.5 | K8: 0 | M8: S03
A9: 2026-02-26 | B9: MZ-PL1-25A | C9: Weeding | G9: kg | H9: 0 | I9: 10 | J9: 0 | K9: 0 | M9: S03
A10: 2025-11-23 | B10: SB-PL2-25A | C10: Land prep | G10: kg | H10: 261 | I10: 8 | J10: 3 | K10: 0 | M10: S03
A11: 2025-11-28 | B11: SB-PL2-25A | C11: Planting | G11: kg | H11: 0 | I11: 6 | J11: 1 | K11: 0 | M11: S03
A12: 2025-12-25 | B12: SB-PL2-25A | C12: Basal fert | D12: Compound D | E12: 300 kg/ha | F12: 2400 | G12: kg | H12: 676 | I12: 4 | J12: 1 | K12: 0 | M12: S03
A13: 2026-01-24 | B13: SB-PL2-25A | C13: Top dressing | D13: AN | E13: 150 kg/ha | F13: 1200 | G13: kg | H13: 499 | I13: 3 | J13: 1 | K13: 0 | M13: S03
A14: 2026-02-11 | B14: SB-PL2-25A | C14: Herbicide | D14: Glyphosate | E14: 3 l/ha | F14: 24 | G14: litre | H14: 179 | I14: 3 | J14: 0.5 | K14: 0 | M14: S03
A15: 2026-03-12 | B15: SB-PL2-25A | C15: Weeding | G15: kg | H15: 0 | I15: 10 | J15: 0 | K15: 0 | M15: S03
A16: 2025-11-27 | B16: GN-PL3-25A | C16: Land prep | G16: kg | H16: 177 | I16: 8 | J16: 3 | K16: 0 | M16: S03
A17: 2025-12-02 | B17: GN-PL3-25A | C17: Planting | G17: kg | H17: 0 | I17: 6 | J17: 1 | K17: 0 | M17: S03
A18: 2026-01-01 | B18: GN-PL3-25A | C18: Basal fert | D18: Compound D | E18: 300 kg/ha | F18: 1500 | G18: kg | H18: 439 | I18: 4 | J18: 1 | K18: 0 | M18: S03
A19: 2026-01-26 | B19: GN-PL3-25A | C19: Top dressing | D19: AN | E19: 150 kg/ha | F19: 750 | G19: kg | H19: 337 | I19: 3 | J19: 1 | K19: 0 | M19: S03
A20: 2026-02-13 | B20: GN-PL3-25A | C20: Herbicide | D20: Glyphosate | E20: 3 l/ha | F20: 15 | G20: litre | H20: 114 | I20: 3 | J20: 0.5 | K20: 0 | M20: S03
A21: 2026-03-08 | B21: GN-PL3-25A | C21: Weeding | G21: kg | H21: 0 | I21: 10 | J21: 0 | K21: 0 | M21: S03
A22: 2026-05-05 | B22: TM-PL1-26A | C22: Land prep | G22: kg | H22: 75 | I22: 8 | J22: 3 | K22: 0 | M22: S03
A23: 2026-05-10 | B23: TM-PL1-26A | C23: Planting | G23: kg | H23: 0 | I23: 6 | J23: 1 | K23: 0 | M23: S03
A24: 2026-06-02 | B24: TM-PL1-26A | C24: Basal fert | D24: Compound D | E24: 300 kg/ha | F24: 600 | G24: kg | H24: 188 | I24: 4 | J24: 1 | K24: 0 | M24: S03
A25: 2026-06-23 | B25: TM-PL1-26A | C25: Top dressing | D25: AN | E25: 150 kg/ha | F25: 300 | G25: kg | H25: 126 | I25: 3 | J25: 1 | K25: 0 | M25: S03
A26: 2026-07-12 | B26: TM-PL1-26A | C26: Herbicide | D26: Glyphosate | E26: 3 l/ha | F26: 6 | G26: litre | H26: 45 | I26: 3 | J26: 0.5 | K26: 0 | M26: S03
A27: 2026-08-07 | B27: TM-PL1-26A | C27: Weeding | G27: kg | H27: 0 | I27: 10 | J27: 0 | K27: 0 | M27: S03
A28: 2026-05-27 | B28: TM-PL2-26A | C28: Land prep | G28: kg | H28: 64 | I28: 8 | J28: 3 | K28: 0 | M28: S03
A29: 2026-06-01 | B29: TM-PL2-26A | C29: Planting | G29: kg | H29: 0 | I29: 6 | J29: 1 | K29: 0 | M29: S03
A30: 2026-06-28 | B30: TM-PL2-26A | C30: Basal fert | D30: Compound D | E30: 300 kg/ha | F30: 600 | G30: kg | H30: 186 | I30: 4 | J30: 1 | K30: 0 | M30: S03
A31: 2026-07-16 | B31: TM-PL2-26A | C31: Top dressing | D31: AN | E31: 150 kg/ha | F31: 300 | G31: kg | H31: 139 | I31: 3 | J31: 1 | K31: 0 | M31: S03
A32: 2026-08-06 | B32: TM-PL2-26A | C32: Herbicide | D32: Glyphosate | E32: 3 l/ha | F32: 6 | G32: litre | H32: 45 | I32: 3 | J32: 0.5 | K32: 0 | M32: S03
A33: 2026-08-25 | B33: TM-PL2-26A | C33: Weeding | G33: kg | H33: 0 | I33: 10 | J33: 0 | K33: 0 | M33: S03

Sheet F4_SCOUTING_LOG
A1: PURPOSE: Pest/disease pressure, growth stage, soil moisture — turns the bot into an agronomy advisor, not just an accountant. | CADENCE: Weekly walk of each planting | ENTERED BY: Field supervisor
A2: date | B2: planting_code | C2: growth_stage | D2: issue_type | E2: issue_name | F2: severity_1_5 | G2: incidence_pct | H2: soil_moisture | I2: action_taken | J2: scouted_by
A3: 2026-01-12 | B3: MZ-P3-2025A | C3: V6 | D3: Pest | E3: Fall armyworm | F3: 2 | G3: 8 | H3: Moist | I3: Spot-sprayed affected rows | J3: S03
A4: 2025-12-04 | B4: MZ-PL1-25A | C4: Emergence | D4: Pest | E4: Aphids | F4: 2 | G4: 15 | H4: Moist | I4: Spot-sprayed affected rows | J4: S03
A5: 2025-12-18 | B5: MZ-PL1-25A | C5: V6 | D5: None | E5: None | G5: 0 | H5: Moist | J5: S03
A6: 2026-01-01 | B6: MZ-PL1-25A | C6: Tasselling | D6: Disease | E6: Grey leaf spot | F6: 2 | G6: 8 | H6: Moist | I6: Spot-sprayed affected rows | J6: S03
A7: 2026-01-15 | B7: MZ-PL1-25A | C7: Silking | D7: None | E7: None | G7: 0 | H7: Moist | J7: S03
A8: 2026-01-29 | B8: MZ-PL1-25A | C8: Grain fill | D8: None | E8: None | G8: 0 | H8: Moist | J8: S03
A9: 2026-02-12 | B9: MZ-PL1-25A | C9: Maturity | D9: Pest | E9: Fall armyworm | F9: 3 | G9: 20 | H9: Moist | I9: Spot-sprayed affected rows | J9: S03
A10: 2026-02-26 | B10: MZ-PL1-25A | C10: Maturity | D10: Nutrient | E10: Nitrogen deficiency | F10: 1 | G10: 11 | H10: Moist | I10: Top-dressed early | J10: S03
A11: 2026-03-12 | B11: MZ-PL1-25A | C11: Maturity | D11: Weed | E11: Witchweed | F11: 3 | G11: 12 | H11: Moist | I11: Hand-weeded | J11: S03
A12: 2026-03-26 | B12: MZ-PL1-25A | C12: Maturity | D12: Pest | E12: Aphids | F12: 2 | G12: 4 | H12: Moist | I12: Spot-sprayed affected rows | J12: S03
A13: 2026-04-09 | B13: MZ-PL1-25A | C13: Maturity | D13: None | E13: None | G13: 0 | H13: Dry | J13: S03
A14: 2025-12-12 | B14: SB-PL2-25A | C14: Emergence | D14: None | E14: None | G14: 0 | H14: Moist | J14: S03
A15: 2025-12-26 | B15: SB-PL2-25A | C15: V6 | D15: Nutrient | E15: Nitrogen deficiency | F15: 1 | G15: 14 | H15: Moist | I15: Top-dressed early | J15: S03
A16: 2026-01-09 | B16: SB-PL2-25A | C16: Tasselling | D16: Pest | E16: Fall armyworm | F16: 1 | G16: 8 | H16: Moist | I16: Spot-sprayed affected rows | J16: S03
A17: 2026-01-23 | B17: SB-PL2-25A | C17: Silking | D17: Weed | E17: Witchweed | F17: 1 | G17: 13 | H17: Moist | I17: Hand-weeded | J17: S03
A18: 2026-02-06 | B18: SB-PL2-25A | C18: Grain fill | D18: None | E18: None | G18: 0 | H18: Moist | J18: S03
A19: 2026-02-20 | B19: SB-PL2-25A | C19: Maturity | D19: Pest | E19: Fall armyworm | F19: 1 | G19: 14 | H19: Moist | I19: Spot-sprayed affected rows | J19: S03
A20: 2026-03-06 | B20: SB-PL2-25A | C20: Maturity | D20: None | E20: None | G20: 0 | H20: Moist | J20: S03
A21: 2026-03-20 | B21: SB-PL2-25A | C21: Maturity | D21: Pest | E21: Aphids | F21: 3 | G21: 20 | H21: Moist | I21: Spot-sprayed affected rows | J21: S03
A22: 2025-12-16 | B22: GN-PL3-25A | C22: Emergence | D22: Pest | E22: Aphids | F22: 2 | G22: 4 | H22: Moist | I22: Spot-sprayed affected rows | J22: S03
A23: 2025-12-30 | B23: GN-PL3-25A | C23: V6 | D23: Weed | E23: Witchweed | F23: 3 | G23: 17 | H23: Moist | I23: Hand-weeded | J23: S03
A24: 2026-01-13 | B24: GN-PL3-25A | C24: Tasselling | D24: Nutrient | E24: Nitrogen deficiency | F24: 2 | G24: 20 | H24: Moist | I24: Top-dressed early | J24: S03
A25: 2026-01-27 | B25: GN-PL3-25A | C25: Silking | D25: None | E25: None | G25: 0 | H25: Moist | J25: S03
A26: 2026-02-10 | B26: GN-PL3-25A | C26: Grain fill | D26: Weed | E26: Witchweed | F26: 1 | G26: 8 | H26: Moist | I26: Hand-weeded | J26: S03
A27: 2026-02-24 | B27: GN-PL3-25A | C27: Maturity | D27: Nutrient | E27: Nitrogen deficiency | F27: 2 | G27: 13 | H27: Moist | I27: Top-dressed early | J27: S03
A28: 2026-03-10 | B28: GN-PL3-25A | C28: Maturity | D28: None | E28: None | G28: 0 | H28: Moist | J28: S03
A29: 2026-03-24 | B29: GN-PL3-25A | C29: Maturity | D29: Weed | E29: Witchweed | F29: 2 | G29: 20 | H29: Moist | I29: Hand-weeded | J29: S03
A30: 2026-04-07 | B30: GN-PL3-25A | C30: Maturity | D30: Pest | E30: Aphids | F30: 1 | G30: 19 | H30: Dry | I30: Spot-sprayed affected rows | J30: S03
A31: 2026-04-21 | B31: GN-PL3-25A | C31: Maturity | D31: Weed | E31: Witchweed | F31: 2 | G31: 11 | H31: Moist | I31: Hand-weeded | J31: S03
A32: 2026-05-24 | B32: TM-PL1-26A | C32: Emergence | D32: Pest | E32: Aphids | F32: 3 | G32: 18 | H32: Dry | I32: Spot-sprayed affected rows | J32: S03
A33: 2026-06-07 | B33: TM-PL1-26A | C33: V6 | D33: Nutrient | E33: Nitrogen deficiency | F33: 2 | G33: 13 | H33: Moist | I33: Top-dressed early | J33: S03
A34: 2026-06-21 | B34: TM-PL1-26A | C34: Tasselling | D34: None | E34: None | G34: 0 | H34: Moist | J34: S03
A35: 2026-07-05 | B35: TM-PL1-26A | C35: Silking | D35: Pest | E35: Fall armyworm | F35: 1 | G35: 19 | H35: Dry | I35: Spot-sprayed affected rows | J35: S03
A36: 2026-07-19 | B36: TM-PL1-26A | C36: Grain fill | D36: Pest | E36: Fall armyworm | F36: 1 | G36: 8 | H36: Dry | I36: Spot-sprayed affected rows | J36: S03
A37: 2026-08-02 | B37: TM-PL1-26A | C37: Maturity | D37: Pest | E37: Aphids | F37: 1 | G37: 18 | H37: Dry | I37: Spot-sprayed affected rows | J37: S03
A38: 2026-08-16 | B38: TM-PL1-26A | C38: Maturity | D38: Pest | E38: Fall armyworm | F38: 1 | G38: 15 | H38: Moist | I38: Spot-sprayed affected rows | J38: S03
A39: 2026-06-15 | B39: TM-PL2-26A | C39: Emergence | D39: None | E39: None | G39: 0 | H39: Dry | J39: S03
A40: 2026-06-29 | B40: TM-PL2-26A | C40: V6 | D40: Disease | E40: Grey leaf spot | F40: 3 | G40: 16 | H40: Moist | I40: Spot-sprayed affected rows | J40: S03
...

Sheet F5_HARVEST_LOG
A1: PURPOSE: Yield, moisture, grade, post-harvest loss. | CADENCE: Per harvest day | ENTERED BY: Supervisor at the scale / bag count
A2: date | B2: planting_code | C2: bags | D2: quantity_kg | E2: moisture_pct | F2: grade | G2: field_loss_kg | H2: storage_location | I2: labour_hours
A3: 2026-04-20 | B3: MZ-P3-2025A | C3: 66 | D3: =C3*50 | E3: 12.5 | F3: A | G3: 40 | H3: Silo 1 | I3: 20
A4: 2026-04-12 | B4: MZ-PL1-25A | C4: 710 | D4: =C4*50 | E4: 12.3 | F4: A | G4: 710 | H4: Silo 1 | I4: 34
A5: 2026-03-28 | B5: SB-PL2-25A | C5: 368 | D5: =C5*50 | E5: 10.2 | F5: A | G5: 368 | H5: Silo 1 | I5: 45
